<?xml version="1.0" ?>

<robot xmlns:xacro="http://www.ros.org/wiki/xacro">

  <xacro:macro name="left_wheel" params="parent">

	<link name="left_wheel_link">
		<inertial>
			<mass value="10.0"/>
			<inertia ixx="0.02708333333" ixy="0.0" ixz="0.0" iyy="0.02708333333" iyz="0.0" izz="0.05"/>
		</inertial>
		<visual>
			<origin xyz="0.0 0.1 0.05" rpy="0.0 1.5707 1.5707"/>
			<geometry name="left_wheel_link_visual">
  				<mesh filename="package://bobble_description/meshes/wheel.dae" scale="1.0 1.0 1.0"/>
			</geometry>
  		</visual>
		<collision>
			<origin xyz="0.0 0.1 0.05" rpy="0.0 1.5707 1.5707"/>
            <geometry>
              <cylinder radius="0.05" length="0.05" />
            </geometry>
			<contact_coefficients kd="1.0" kp="1000.0" mu="0"/>
		</collision>
	</link>

	<gazebo reference="left_wheel_link">
		<selfCollide>true</selfCollide>
	</gazebo>

	<joint name="left_wheel_hinge" type="revolute">
		<parent link="${parent}"/>
		<child link="left_wheel_link"/>
		<origin rpy="0 0 0" xyz="0.0 0.0 0.0"/>
		<axis xyz="0 1 0"/>
		<limit effort="30" lower="-2.6" upper="2.6" velocity="2.0"/>
		<!-- <safety_controller k_velocity="0.5"/> -->
		<!-- <joint_properties damping="100.0" friction="1000.0" /> -->
    	<dynamics damping="0.9" friction="${3.0/7}"/>
	</joint>

	<transmission name="left_wheel_transmission">
		<type>transmission_interface/SimpleTransmission"</type>
		<joint name="left_wheel_hinge">
			<hardwareInterface>hardware_interface/EffortJointInterface</hardwareInterface>
		</joint>
		<actuator name="left_wheel_motor">
			<hardwareInterface>hardware_interface/EffortJointInterface</hardwareInterface>
			<mechanicalReduction>1</mechanicalReduction>
		</actuator>
	</transmission>

  </xacro:macro>

</robot>
